// Vitest Snapshot v1, https://vitest.dev/guide/snapshot.html

exports[`should be able to ignore rule fallback-condition 1`] = `
[
  "[arethetypeswrong] test-fallback-condition v0.0.0

 (ignoring rules: 'fallback-condition')

 No problems found 🌟
┌───────────────────┬───────────────────────────┐
│                   │ "test-fallback-condition" │
├───────────────────┼───────────────────────────┤
│ node10            │ 🟢                        │
├───────────────────┼───────────────────────────┤
│ node16 (from CJS) │ 🟢 (CJS)                  │
├───────────────────┼───────────────────────────┤
│ node16 (from ESM) │ 🟢 (CJS)                  │
├───────────────────┼───────────────────────────┤
│ bundler           │ 🟢                        │
└───────────────────┴───────────────────────────┘",
]
`;

exports[`should failed on fallback-condition 2`] = `
[
  "[arethetypeswrong] test-fallback-condition v0.0.0

🐛 Import resolved to types through a conditional package.json export, but only after failing to resolve through an earlier condition. This behavior is a TypeScript bug (https://github.com/microsoft/TypeScript/issues/50762). It may misrepresent the runtime behavior of this import and should not be relied upon. https://github.com/arethetypeswrong/arethetypeswrong.github.io/blob/main/docs/problems/FallbackCondition.md


┌───────────────────┬────────────────────────────┐
│                   │ "test-fallback-condition"  │
├───────────────────┼────────────────────────────┤
│ node10            │ 🟢                         │
├───────────────────┼────────────────────────────┤
│ node16 (from CJS) │ 🟢 (CJS)                   │
├───────────────────┼────────────────────────────┤
│ node16 (from ESM) │ 🐛 Used fallback condition │
├───────────────────┼────────────────────────────┤
│ bundler           │ 🐛 Used fallback condition │
└───────────────────┴────────────────────────────┘",
]
`;
